2023-10-19 07:23:43 | ERROR    | __main__:run:144 | An error has been caught in function 'run', process 'MainProcess' (3544), thread 'MainThread' (140206948445248): - {}
Traceback (most recent call last):
  File "/home/runner/work/myEpic/myEpic/epic/src/claim.py", line 148, in <module>
    asyncio.run(run())
  File "/opt/hostedtoolcache/Python/3.10.13/x64/lib/python3.10/asyncio/runners.py", line 44, in run
    return loop.run_until_complete(main)
  File "/opt/hostedtoolcache/Python/3.10.13/x64/lib/python3.10/asyncio/base_events.py", line 636, in run_until_complete
    self.run_forever()
  File "/opt/hostedtoolcache/Python/3.10.13/x64/lib/python3.10/asyncio/base_events.py", line 603, in run_forever
    self._run_once()
  File "/opt/hostedtoolcache/Python/3.10.13/x64/lib/python3.10/asyncio/base_events.py", line 1909, in _run_once
    handle._run()
  File "/opt/hostedtoolcache/Python/3.10.13/x64/lib/python3.10/asyncio/events.py", line 80, in _run
    self._context.run(self._callback, *self._args)
> File "/home/runner/work/myEpic/myEpic/epic/src/claim.py", line 144, in run
    await agent.stash()
  File "/home/runner/work/myEpic/myEpic/epic/src/claim.py", line 137, in stash
    await self.claim_epic_games(context)
  File "/home/runner/work/myEpic/myEpic/epic/src/claim.py", line 92, in claim_epic_games
    if await epic.authorize(page):
  File "/home/runner/work/myEpic/myEpic/epic/src/epic_games/agent.py", line 208, in authorize
    match await self._login(page):
  File "/home/runner/work/myEpic/myEpic/epic/src/epic_games/agent.py", line 194, in _login
    await insert_challenge(stage="email_exists_prod")
  File "/home/runner/work/myEpic/myEpic/epic/src/epic_games/agent.py", line 173, in insert_challenge
    await page.click("#sign-in", delay=200)
  File "/opt/hostedtoolcache/Python/3.10.13/x64/lib/python3.10/site-packages/playwright/async_api/_generated.py", line 10101, in click
    await self._impl_obj.click(
  File "/opt/hostedtoolcache/Python/3.10.13/x64/lib/python3.10/site-packages/playwright/_impl/_page.py", line 691, in click
    return await self._main_frame.click(**locals_to_params(locals()))
  File "/opt/hostedtoolcache/Python/3.10.13/x64/lib/python3.10/site-packages/playwright/_impl/_frame.py", line 483, in click
    await self._channel.send("click", locals_to_params(locals()))
  File "/opt/hostedtoolcache/Python/3.10.13/x64/lib/python3.10/site-packages/playwright/_impl/_connection.py", line 61, in send
    return await self._connection.wrap_api_call(
  File "/opt/hostedtoolcache/Python/3.10.13/x64/lib/python3.10/site-packages/playwright/_impl/_connection.py", line 490, in wrap_api_call
    return await cb()
  File "/opt/hostedtoolcache/Python/3.10.13/x64/lib/python3.10/site-packages/playwright/_impl/_connection.py", line 99, in inner_send
    result = next(iter(done)).result()
playwright._impl._api_types.TimeoutError: Timeout 30000ms exceeded.
=========================== logs ===========================
waiting for locator("#sign-in")
============================================================
