2023-12-01 06:31:48 | ERROR    | __main__:run:158 | An error has been caught in function 'run', process 'MainProcess' (3678), thread 'MainThread' (140716305021824): - {}
Traceback (most recent call last):
  File "/home/runner/work/myEpic/myEpic/epic/src/claim.py", line 162, in <module>
    asyncio.run(run())
  File "/opt/hostedtoolcache/Python/3.10.13/x64/lib/python3.10/asyncio/runners.py", line 44, in run
    return loop.run_until_complete(main)
  File "/opt/hostedtoolcache/Python/3.10.13/x64/lib/python3.10/asyncio/base_events.py", line 636, in run_until_complete
    self.run_forever()
  File "/opt/hostedtoolcache/Python/3.10.13/x64/lib/python3.10/asyncio/base_events.py", line 603, in run_forever
    self._run_once()
  File "/opt/hostedtoolcache/Python/3.10.13/x64/lib/python3.10/asyncio/base_events.py", line 1909, in _run_once
    handle._run()
  File "/opt/hostedtoolcache/Python/3.10.13/x64/lib/python3.10/asyncio/events.py", line 80, in _run
    self._context.run(self._callback, *self._args)
> File "/home/runner/work/myEpic/myEpic/epic/src/claim.py", line 158, in run
    await agent.stash()
  File "/home/runner/work/myEpic/myEpic/epic/src/claim.py", line 151, in stash
    await self.claim_epic_games(context)
  File "/home/runner/work/myEpic/myEpic/epic/src/claim.py", line 99, in claim_epic_games
    cookies = await epic.flush_token(context)
  File "/home/runner/work/myEpic/myEpic/epic/src/epic_games/agent.py", line 273, in flush_token
    await page.goto("https://www.epicgames.com/account/personal", wait_until="networkidle")
  File "/opt/hostedtoolcache/Python/3.10.13/x64/lib/python3.10/site-packages/playwright/async_api/_generated.py", line 9260, in goto
    await self._impl_obj.goto(
  File "/opt/hostedtoolcache/Python/3.10.13/x64/lib/python3.10/site-packages/playwright/_impl/_page.py", line 475, in goto
    return await self._main_frame.goto(**locals_to_params(locals()))
  File "/opt/hostedtoolcache/Python/3.10.13/x64/lib/python3.10/site-packages/playwright/_impl/_frame.py", line 139, in goto
    await self._channel.send("goto", locals_to_params(locals()))
  File "/opt/hostedtoolcache/Python/3.10.13/x64/lib/python3.10/site-packages/playwright/_impl/_connection.py", line 62, in send
    return await self._connection.wrap_api_call(
  File "/opt/hostedtoolcache/Python/3.10.13/x64/lib/python3.10/site-packages/playwright/_impl/_connection.py", line 492, in wrap_api_call
    return await cb()
  File "/opt/hostedtoolcache/Python/3.10.13/x64/lib/python3.10/site-packages/playwright/_impl/_connection.py", line 100, in inner_send
    result = next(iter(done)).result()
playwright._impl._errors.TimeoutError: Timeout 30000ms exceeded.
