2023-12-19 06:32:34 | ERROR    | __main__:run:158 | An error has been caught in function 'run', process 'MainProcess' (3675), thread 'MainThread' (140640822131584): - {}
Traceback (most recent call last):
  File "/home/runner/work/myEpic/myEpic/epic/src/claim.py", line 162, in <module>
    asyncio.run(run())
  File "/opt/hostedtoolcache/Python/3.10.13/x64/lib/python3.10/asyncio/runners.py", line 44, in run
    return loop.run_until_complete(main)
  File "/opt/hostedtoolcache/Python/3.10.13/x64/lib/python3.10/asyncio/base_events.py", line 636, in run_until_complete
    self.run_forever()
  File "/opt/hostedtoolcache/Python/3.10.13/x64/lib/python3.10/asyncio/base_events.py", line 603, in run_forever
    self._run_once()
  File "/opt/hostedtoolcache/Python/3.10.13/x64/lib/python3.10/asyncio/base_events.py", line 1909, in _run_once
    handle._run()
  File "/opt/hostedtoolcache/Python/3.10.13/x64/lib/python3.10/asyncio/events.py", line 80, in _run
    self._context.run(self._callback, *self._args)
> File "/home/runner/work/myEpic/myEpic/epic/src/claim.py", line 158, in run
    await agent.stash()
  File "/home/runner/work/myEpic/myEpic/epic/src/claim.py", line 151, in stash
    await self.claim_epic_games(context)
  File "/home/runner/work/myEpic/myEpic/epic/src/claim.py", line 122, in claim_epic_games
    await epic.claim_weekly_games(page, single_promotions)
  File "/opt/hostedtoolcache/Python/3.10.13/x64/lib/python3.10/site-packages/tenacity/_asyncio.py", line 88, in async_wrapped
    return await fn(*args, **kwargs)
  File "/opt/hostedtoolcache/Python/3.10.13/x64/lib/python3.10/site-packages/tenacity/_asyncio.py", line 47, in __call__
    do = self.iter(retry_state=retry_state)
  File "/opt/hostedtoolcache/Python/3.10.13/x64/lib/python3.10/site-packages/tenacity/__init__.py", line 325, in iter
    raise retry_exc.reraise()
  File "/opt/hostedtoolcache/Python/3.10.13/x64/lib/python3.10/site-packages/tenacity/__init__.py", line 158, in reraise
    raise self.last_attempt.result()
  File "/opt/hostedtoolcache/Python/3.10.13/x64/lib/python3.10/concurrent/futures/_base.py", line 451, in result
    return self.__get_result()
  File "/opt/hostedtoolcache/Python/3.10.13/x64/lib/python3.10/concurrent/futures/_base.py", line 403, in __get_result
    raise self._exception
  File "/opt/hostedtoolcache/Python/3.10.13/x64/lib/python3.10/site-packages/tenacity/_asyncio.py", line 50, in __call__
    result = await fn(*args, **kwargs)
  File "/home/runner/work/myEpic/myEpic/epic/src/epic_games/agent.py", line 320, in claim_weekly_games
    await page.click("//button//span[text()='Check Out']")
  File "/opt/hostedtoolcache/Python/3.10.13/x64/lib/python3.10/site-packages/playwright/async_api/_generated.py", line 10117, in click
    await self._impl_obj.click(
  File "/opt/hostedtoolcache/Python/3.10.13/x64/lib/python3.10/site-packages/playwright/_impl/_page.py", line 694, in click
    return await self._main_frame.click(**locals_to_params(locals()))
  File "/opt/hostedtoolcache/Python/3.10.13/x64/lib/python3.10/site-packages/playwright/_impl/_frame.py", line 484, in click
    await self._channel.send("click", locals_to_params(locals()))
  File "/opt/hostedtoolcache/Python/3.10.13/x64/lib/python3.10/site-packages/playwright/_impl/_connection.py", line 62, in send
    return await self._connection.wrap_api_call(
  File "/opt/hostedtoolcache/Python/3.10.13/x64/lib/python3.10/site-packages/playwright/_impl/_connection.py", line 492, in wrap_api_call
    return await cb()
  File "/opt/hostedtoolcache/Python/3.10.13/x64/lib/python3.10/site-packages/playwright/_impl/_connection.py", line 100, in inner_send
    result = next(iter(done)).result()
playwright._impl._errors.TimeoutError: Timeout 30000ms exceeded.
