2024-02-24 06:29:14 | INFO    | __main__:stash:131 | run - {'image': '20231121', 'version': '0.10.1.post2', 'role': 'EpicPlayer', 'headless': True}
2024-02-24 06:29:22 | WARNING    | epic_games.agent:get_order_history:467 | Failed to get order history, cookie may have expired - {}
2024-02-24 06:29:23 | DEBUG    | __main__:create_tasks:66 | Put task - {'title': 'Super Meat Boy Forever', 'url': 'https://store.epicgames.com/en-US/p/super-meat-boy-forever'}
2024-02-24 06:29:27 | INFO    | epic_games.agent:claim_weekly_games:294 | claim_weekly_games - {'action': 'go to store', 'url': 'https://store.epicgames.com/en-US/p/super-meat-boy-forever'}
2024-02-24 06:29:36 | INFO    | epic_games.agent:claim_weekly_games:326 | claim_weekly_games - {'action': 'move to webPurchaseContainer iframe'}
2024-02-24 06:29:38 | INFO    | epic_games.agent:claim_weekly_games:328 | claim_weekly_games - {'action': 'click payment button'}
2024-02-24 06:29:39 | ERROR    | hcaptcha_challenger.agents.playwright.control:handler:153 | 'utf-8' codec can't decode bytes in position 0-1: invalid continuation byte - {}
Traceback (most recent call last):
  File "/home/runner/work/myEpic/myEpic/epic/src/claim.py", line 162, in <module>
    asyncio.run(run())
  File "/opt/hostedtoolcache/Python/3.10.13/x64/lib/python3.10/asyncio/runners.py", line 44, in run
    return loop.run_until_complete(main)
  File "/opt/hostedtoolcache/Python/3.10.13/x64/lib/python3.10/asyncio/base_events.py", line 636, in run_until_complete
    self.run_forever()
  File "/opt/hostedtoolcache/Python/3.10.13/x64/lib/python3.10/asyncio/base_events.py", line 603, in run_forever
    self._run_once()
  File "/opt/hostedtoolcache/Python/3.10.13/x64/lib/python3.10/asyncio/base_events.py", line 1909, in _run_once
    handle._run()
  File "/opt/hostedtoolcache/Python/3.10.13/x64/lib/python3.10/asyncio/events.py", line 80, in _run
    self._context.run(self._callback, *self._args)
> File "/opt/hostedtoolcache/Python/3.10.13/x64/lib/python3.10/site-packages/hcaptcha_challenger/agents/playwright/control.py", line 145, in handler
    data = await response.json()
  File "/opt/hostedtoolcache/Python/3.10.13/x64/lib/python3.10/site-packages/playwright/async_api/_generated.py", line 636, in json
    return mapping.from_maybe_impl(await self._impl_obj.json())
  File "/opt/hostedtoolcache/Python/3.10.13/x64/lib/python3.10/site-packages/playwright/_impl/_network.py", line 616, in json
    return json.loads(await self.text())
  File "/opt/hostedtoolcache/Python/3.10.13/x64/lib/python3.10/site-packages/playwright/_impl/_network.py", line 613, in text
    return content.decode()
UnicodeDecodeError: 'utf-8' codec can't decode bytes in position 0-1: invalid continuation byte
2024-02-24 06:30:13 | ERROR    | hcaptcha_challenger.agents.playwright.control:execute:615 | task interrupt <backcall> - {'reason': 'Failed to obtain challenge task'}
2024-02-24 06:30:13 | DEBUG    | epic_games.agent:insert_challenge:106 | task done - {'sattus': 'success'}
2024-02-24 06:30:15 | ERROR    | hcaptcha_challenger.agents.playwright.control:handler:153 | 'utf-8' codec can't decode byte 0xf4 in position 1: invalid continuation byte - {}
Traceback (most recent call last):
  File "/home/runner/work/myEpic/myEpic/epic/src/claim.py", line 162, in <module>
    asyncio.run(run())
  File "/opt/hostedtoolcache/Python/3.10.13/x64/lib/python3.10/asyncio/runners.py", line 44, in run
    return loop.run_until_complete(main)
  File "/opt/hostedtoolcache/Python/3.10.13/x64/lib/python3.10/asyncio/base_events.py", line 636, in run_until_complete
    self.run_forever()
  File "/opt/hostedtoolcache/Python/3.10.13/x64/lib/python3.10/asyncio/base_events.py", line 603, in run_forever
    self._run_once()
  File "/opt/hostedtoolcache/Python/3.10.13/x64/lib/python3.10/asyncio/base_events.py", line 1909, in _run_once
    handle._run()
  File "/opt/hostedtoolcache/Python/3.10.13/x64/lib/python3.10/asyncio/events.py", line 80, in _run
    self._context.run(self._callback, *self._args)
> File "/opt/hostedtoolcache/Python/3.10.13/x64/lib/python3.10/site-packages/hcaptcha_challenger/agents/playwright/control.py", line 145, in handler
    data = await response.json()
  File "/opt/hostedtoolcache/Python/3.10.13/x64/lib/python3.10/site-packages/playwright/async_api/_generated.py", line 636, in json
    return mapping.from_maybe_impl(await self._impl_obj.json())
  File "/opt/hostedtoolcache/Python/3.10.13/x64/lib/python3.10/site-packages/playwright/_impl/_network.py", line 616, in json
    return json.loads(await self.text())
  File "/opt/hostedtoolcache/Python/3.10.13/x64/lib/python3.10/site-packages/playwright/_impl/_network.py", line 613, in text
    return content.decode()
UnicodeDecodeError: 'utf-8' codec can't decode byte 0xf4 in position 1: invalid continuation byte
2024-02-24 06:30:45 | INFO    | epic_games.agent:claim_weekly_games:294 | claim_weekly_games - {'action': 'go to store', 'url': 'https://store.epicgames.com/en-US/p/super-meat-boy-forever'}
2024-02-24 06:30:53 | INFO    | epic_games.agent:claim_weekly_games:326 | claim_weekly_games - {'action': 'move to webPurchaseContainer iframe'}
2024-02-24 06:30:59 | INFO    | epic_games.agent:claim_weekly_games:328 | claim_weekly_games - {'action': 'click payment button'}
2024-02-24 06:30:59 | ERROR    | hcaptcha_challenger.agents.playwright.control:handler:153 | 'utf-8' codec can't decode bytes in position 0-1: invalid continuation byte - {}
Traceback (most recent call last):
  File "/home/runner/work/myEpic/myEpic/epic/src/claim.py", line 162, in <module>
    asyncio.run(run())
  File "/opt/hostedtoolcache/Python/3.10.13/x64/lib/python3.10/asyncio/runners.py", line 44, in run
    return loop.run_until_complete(main)
  File "/opt/hostedtoolcache/Python/3.10.13/x64/lib/python3.10/asyncio/base_events.py", line 636, in run_until_complete
    self.run_forever()
  File "/opt/hostedtoolcache/Python/3.10.13/x64/lib/python3.10/asyncio/base_events.py", line 603, in run_forever
    self._run_once()
  File "/opt/hostedtoolcache/Python/3.10.13/x64/lib/python3.10/asyncio/base_events.py", line 1909, in _run_once
    handle._run()
  File "/opt/hostedtoolcache/Python/3.10.13/x64/lib/python3.10/asyncio/events.py", line 80, in _run
    self._context.run(self._callback, *self._args)
> File "/opt/hostedtoolcache/Python/3.10.13/x64/lib/python3.10/site-packages/hcaptcha_challenger/agents/playwright/control.py", line 145, in handler
    data = await response.json()
  File "/opt/hostedtoolcache/Python/3.10.13/x64/lib/python3.10/site-packages/playwright/async_api/_generated.py", line 636, in json
    return mapping.from_maybe_impl(await self._impl_obj.json())
  File "/opt/hostedtoolcache/Python/3.10.13/x64/lib/python3.10/site-packages/playwright/_impl/_network.py", line 616, in json
    return json.loads(await self.text())
  File "/opt/hostedtoolcache/Python/3.10.13/x64/lib/python3.10/site-packages/playwright/_impl/_network.py", line 613, in text
    return content.decode()
UnicodeDecodeError: 'utf-8' codec can't decode bytes in position 0-1: invalid continuation byte
2024-02-24 06:31:33 | ERROR    | hcaptcha_challenger.agents.playwright.control:execute:615 | task interrupt <backcall> - {'reason': 'Failed to obtain challenge task'}
2024-02-24 06:31:33 | DEBUG    | epic_games.agent:insert_challenge:106 | task done - {'sattus': 'success'}
2024-02-24 06:31:36 | ERROR    | hcaptcha_challenger.agents.playwright.control:handler:153 | 'utf-8' codec can't decode byte 0xae in position 2: invalid start byte - {}
Traceback (most recent call last):
  File "/home/runner/work/myEpic/myEpic/epic/src/claim.py", line 162, in <module>
    asyncio.run(run())
  File "/opt/hostedtoolcache/Python/3.10.13/x64/lib/python3.10/asyncio/runners.py", line 44, in run
    return loop.run_until_complete(main)
  File "/opt/hostedtoolcache/Python/3.10.13/x64/lib/python3.10/asyncio/base_events.py", line 636, in run_until_complete
    self.run_forever()
  File "/opt/hostedtoolcache/Python/3.10.13/x64/lib/python3.10/asyncio/base_events.py", line 603, in run_forever
    self._run_once()
  File "/opt/hostedtoolcache/Python/3.10.13/x64/lib/python3.10/asyncio/base_events.py", line 1909, in _run_once
    handle._run()
  File "/opt/hostedtoolcache/Python/3.10.13/x64/lib/python3.10/asyncio/events.py", line 80, in _run
    self._context.run(self._callback, *self._args)
> File "/opt/hostedtoolcache/Python/3.10.13/x64/lib/python3.10/site-packages/hcaptcha_challenger/agents/playwright/control.py", line 145, in handler
    data = await response.json()
  File "/opt/hostedtoolcache/Python/3.10.13/x64/lib/python3.10/site-packages/playwright/async_api/_generated.py", line 636, in json
    return mapping.from_maybe_impl(await self._impl_obj.json())
  File "/opt/hostedtoolcache/Python/3.10.13/x64/lib/python3.10/site-packages/playwright/_impl/_network.py", line 616, in json
    return json.loads(await self.text())
  File "/opt/hostedtoolcache/Python/3.10.13/x64/lib/python3.10/site-packages/playwright/_impl/_network.py", line 613, in text
    return content.decode()
UnicodeDecodeError: 'utf-8' codec can't decode byte 0xae in position 2: invalid start byte
2024-02-24 06:32:05 | INFO    | epic_games.agent:claim_weekly_games:294 | claim_weekly_games - {'action': 'go to store', 'url': 'https://store.epicgames.com/en-US/p/super-meat-boy-forever'}
2024-02-24 06:32:14 | INFO    | epic_games.agent:claim_weekly_games:326 | claim_weekly_games - {'action': 'move to webPurchaseContainer iframe'}
2024-02-24 06:32:16 | INFO    | epic_games.agent:claim_weekly_games:328 | claim_weekly_games - {'action': 'click payment button'}
2024-02-24 06:32:17 | ERROR    | hcaptcha_challenger.agents.playwright.control:handler:153 | 'utf-8' codec can't decode byte 0xc8 in position 0: invalid continuation byte - {}
Traceback (most recent call last):
  File "/home/runner/work/myEpic/myEpic/epic/src/claim.py", line 162, in <module>
    asyncio.run(run())
  File "/opt/hostedtoolcache/Python/3.10.13/x64/lib/python3.10/asyncio/runners.py", line 44, in run
    return loop.run_until_complete(main)
  File "/opt/hostedtoolcache/Python/3.10.13/x64/lib/python3.10/asyncio/base_events.py", line 636, in run_until_complete
    self.run_forever()
  File "/opt/hostedtoolcache/Python/3.10.13/x64/lib/python3.10/asyncio/base_events.py", line 603, in run_forever
    self._run_once()
  File "/opt/hostedtoolcache/Python/3.10.13/x64/lib/python3.10/asyncio/base_events.py", line 1909, in _run_once
    handle._run()
  File "/opt/hostedtoolcache/Python/3.10.13/x64/lib/python3.10/asyncio/events.py", line 80, in _run
    self._context.run(self._callback, *self._args)
> File "/opt/hostedtoolcache/Python/3.10.13/x64/lib/python3.10/site-packages/hcaptcha_challenger/agents/playwright/control.py", line 145, in handler
    data = await response.json()
  File "/opt/hostedtoolcache/Python/3.10.13/x64/lib/python3.10/site-packages/playwright/async_api/_generated.py", line 636, in json
    return mapping.from_maybe_impl(await self._impl_obj.json())
  File "/opt/hostedtoolcache/Python/3.10.13/x64/lib/python3.10/site-packages/playwright/_impl/_network.py", line 616, in json
    return json.loads(await self.text())
  File "/opt/hostedtoolcache/Python/3.10.13/x64/lib/python3.10/site-packages/playwright/_impl/_network.py", line 613, in text
    return content.decode()
UnicodeDecodeError: 'utf-8' codec can't decode byte 0xc8 in position 0: invalid continuation byte
2024-02-24 06:32:51 | ERROR    | hcaptcha_challenger.agents.playwright.control:execute:615 | task interrupt <backcall> - {'reason': 'Failed to obtain challenge task'}
2024-02-24 06:32:51 | DEBUG    | epic_games.agent:insert_challenge:106 | task done - {'sattus': 'success'}
2024-02-24 06:32:53 | ERROR    | hcaptcha_challenger.agents.playwright.control:handler:153 | 'utf-8' codec can't decode byte 0xde in position 1: invalid continuation byte - {}
Traceback (most recent call last):
  File "/home/runner/work/myEpic/myEpic/epic/src/claim.py", line 162, in <module>
    asyncio.run(run())
  File "/opt/hostedtoolcache/Python/3.10.13/x64/lib/python3.10/asyncio/runners.py", line 44, in run
    return loop.run_until_complete(main)
  File "/opt/hostedtoolcache/Python/3.10.13/x64/lib/python3.10/asyncio/base_events.py", line 636, in run_until_complete
    self.run_forever()
  File "/opt/hostedtoolcache/Python/3.10.13/x64/lib/python3.10/asyncio/base_events.py", line 603, in run_forever
    self._run_once()
  File "/opt/hostedtoolcache/Python/3.10.13/x64/lib/python3.10/asyncio/base_events.py", line 1909, in _run_once
    handle._run()
  File "/opt/hostedtoolcache/Python/3.10.13/x64/lib/python3.10/asyncio/events.py", line 80, in _run
    self._context.run(self._callback, *self._args)
> File "/opt/hostedtoolcache/Python/3.10.13/x64/lib/python3.10/site-packages/hcaptcha_challenger/agents/playwright/control.py", line 145, in handler
    data = await response.json()
  File "/opt/hostedtoolcache/Python/3.10.13/x64/lib/python3.10/site-packages/playwright/async_api/_generated.py", line 636, in json
    return mapping.from_maybe_impl(await self._impl_obj.json())
  File "/opt/hostedtoolcache/Python/3.10.13/x64/lib/python3.10/site-packages/playwright/_impl/_network.py", line 616, in json
    return json.loads(await self.text())
  File "/opt/hostedtoolcache/Python/3.10.13/x64/lib/python3.10/site-packages/playwright/_impl/_network.py", line 613, in text
    return content.decode()
UnicodeDecodeError: 'utf-8' codec can't decode byte 0xde in position 1: invalid continuation byte
2024-02-24 06:33:23 | ERROR    | __main__:run:158 | An error has been caught in function 'run', process 'MainProcess' (3538), thread 'MainThread' (139755601619840): - {}
Traceback (most recent call last):
  File "/home/runner/work/myEpic/myEpic/epic/src/claim.py", line 151, in stash
    await self.claim_epic_games(context)
  File "/home/runner/work/myEpic/myEpic/epic/src/claim.py", line 122, in claim_epic_games
    await epic.claim_weekly_games(page, single_promotions)
  File "/opt/hostedtoolcache/Python/3.10.13/x64/lib/python3.10/site-packages/tenacity/_asyncio.py", line 88, in async_wrapped
    return await fn(*args, **kwargs)
  File "/opt/hostedtoolcache/Python/3.10.13/x64/lib/python3.10/site-packages/tenacity/_asyncio.py", line 47, in __call__
    do = self.iter(retry_state=retry_state)
  File "/opt/hostedtoolcache/Python/3.10.13/x64/lib/python3.10/site-packages/tenacity/__init__.py", line 325, in iter
    raise retry_exc.reraise()
  File "/opt/hostedtoolcache/Python/3.10.13/x64/lib/python3.10/site-packages/tenacity/__init__.py", line 158, in reraise
    raise self.last_attempt.result()
  File "/opt/hostedtoolcache/Python/3.10.13/x64/lib/python3.10/concurrent/futures/_base.py", line 451, in result
    return self.__get_result()
  File "/opt/hostedtoolcache/Python/3.10.13/x64/lib/python3.10/concurrent/futures/_base.py", line 403, in __get_result
    raise self._exception
  File "/opt/hostedtoolcache/Python/3.10.13/x64/lib/python3.10/site-packages/tenacity/_asyncio.py", line 50, in __call__
    result = await fn(*args, **kwargs)
  File "/home/runner/work/myEpic/myEpic/epic/src/epic_games/agent.py", line 338, in claim_weekly_games
    await page.wait_for_url(recur_url)
  File "/opt/hostedtoolcache/Python/3.10.13/x64/lib/python3.10/site-packages/playwright/async_api/_generated.py", line 9432, in wait_for_url
    await self._impl_obj.wait_for_url(
  File "/opt/hostedtoolcache/Python/3.10.13/x64/lib/python3.10/site-packages/playwright/_impl/_page.py", line 508, in wait_for_url
    return await self._main_frame.wait_for_url(**locals_to_params(locals()))
  File "/opt/hostedtoolcache/Python/3.10.13/x64/lib/python3.10/site-packages/playwright/_impl/_frame.py", line 237, in wait_for_url
    async with self.expect_navigation(
  File "/opt/hostedtoolcache/Python/3.10.13/x64/lib/python3.10/site-packages/playwright/_impl/_event_context_manager.py", line 33, in __aexit__
    await self._future
  File "/opt/hostedtoolcache/Python/3.10.13/x64/lib/python3.10/site-packages/playwright/_impl/_frame.py", line 212, in continuation
    event = await waiter.result()
playwright._impl._errors.TimeoutError: Timeout 30000ms exceeded.
=========================== logs ===========================
waiting for navigation to "https://store.epicgames.com/en-US/cart/success" until 'load'
============================================================

During handling of the above exception, another exception occurred:

Traceback (most recent call last):
  File "/home/runner/work/myEpic/myEpic/epic/src/claim.py", line 162, in <module>
    asyncio.run(run())
  File "/opt/hostedtoolcache/Python/3.10.13/x64/lib/python3.10/asyncio/runners.py", line 44, in run
    return loop.run_until_complete(main)
  File "/opt/hostedtoolcache/Python/3.10.13/x64/lib/python3.10/asyncio/base_events.py", line 636, in run_until_complete
    self.run_forever()
  File "/opt/hostedtoolcache/Python/3.10.13/x64/lib/python3.10/asyncio/base_events.py", line 603, in run_forever
    self._run_once()
  File "/opt/hostedtoolcache/Python/3.10.13/x64/lib/python3.10/asyncio/base_events.py", line 1909, in _run_once
    handle._run()
  File "/opt/hostedtoolcache/Python/3.10.13/x64/lib/python3.10/asyncio/events.py", line 80, in _run
    self._context.run(self._callback, *self._args)
> File "/home/runner/work/myEpic/myEpic/epic/src/claim.py", line 158, in run
    await agent.stash()
  File "/home/runner/work/myEpic/myEpic/epic/src/claim.py", line 139, in stash
    async with async_playwright() as p:
  File "/opt/hostedtoolcache/Python/3.10.13/x64/lib/python3.10/site-packages/playwright/async_api/_context_manager.py", line 58, in __aexit__
    await self._connection.stop_async()
  File "/opt/hostedtoolcache/Python/3.10.13/x64/lib/python3.10/site-packages/playwright/_impl/_connection.py", line 289, in stop_async
    self.cleanup()
  File "/opt/hostedtoolcache/Python/3.10.13/x64/lib/python3.10/site-packages/playwright/_impl/_connection.py", line 300, in cleanup
    callback.future.set_exception(self._closed_error)
asyncio.exceptions.InvalidStateError: invalid state
