2024-01-24 06:32:27 | INFO    | __main__:stash:131 | run - {'image': '20231121', 'version': '0.10.1.post2', 'role': 'EpicPlayer', 'headless': True}
2024-01-24 06:32:36 | INFO    | __main__:claim_epic_games:97 | Try to flush cookie - {'task': 'claim_epic_games'}
2024-01-24 06:32:38 | SUCCESS    | epic_games.agent:_login:253 | login - {'result': 'Successfully refreshed tokens'}
2024-01-24 06:32:48 | SUCCESS    | epic_games.agent:flush_token:280 | flush_token - {'path': PosixPath('/home/runner/work/myEpic/myEpic/epic/user_data_dir/epic-games@yiyindaren/ctx_cookie.json')}
2024-01-24 06:32:48 | WARNING    | epic_games.agent:get_order_history:467 | Failed to get order history, cookie may have expired - {}
2024-01-24 06:32:49 | DEBUG    | __main__:create_tasks:66 | Put task - {'title': 'LOVE', 'url': 'https://store.epicgames.com/en-US/p/love-65c4d0'}
2024-01-24 06:32:49 | INFO    | epic_games.agent:claim_weekly_games:294 | claim_weekly_games - {'action': 'go to store', 'url': 'https://store.epicgames.com/en-US/p/love-65c4d0'}
2024-01-24 06:32:58 | INFO    | epic_games.agent:claim_weekly_games:326 | claim_weekly_games - {'action': 'move to webPurchaseContainer iframe'}
2024-01-24 06:33:00 | INFO    | epic_games.agent:claim_weekly_games:328 | claim_weekly_games - {'action': 'click payment button'}
2024-01-24 06:33:05 | DEBUG    | hcaptcha_challenger.agents.playwright.control:_parse_label:241 | get task - {'prompt': 'Please click each image containing an electronic device'}
2024-01-24 06:33:06 | DEBUG    | hcaptcha_challenger.agents.playwright.control:_rank_models:259 | handle task - {'rank_model': 'nested_electronic_device_mouse2309.onnx', 'prompt': 'Please click each image containing an electronic device'}
2024-01-24 06:33:09 | DEBUG    | epic_games.agent:insert_challenge:106 | task done - {'sattus': 'success'}
2024-01-24 06:33:41 | INFO    | epic_games.agent:claim_weekly_games:294 | claim_weekly_games - {'action': 'go to store', 'url': 'https://store.epicgames.com/en-US/p/love-65c4d0'}
2024-01-24 06:33:50 | INFO    | epic_games.agent:claim_weekly_games:326 | claim_weekly_games - {'action': 'move to webPurchaseContainer iframe'}
2024-01-24 06:33:52 | INFO    | epic_games.agent:claim_weekly_games:328 | claim_weekly_games - {'action': 'click payment button'}
2024-01-24 06:33:57 | DEBUG    | hcaptcha_challenger.agents.playwright.control:_parse_label:241 | get task - {'prompt': 'Please click eacһ image cοntaining an electronic ԁevice'}
2024-01-24 06:33:58 | DEBUG    | hcaptcha_challenger.agents.playwright.control:_catch_all_binary_challenge:474 | handle task - {'unsupervised': 'binary', 'candidate_labels': ['This is a picture that looks like electronic device.', "This is a picture that don't look like electronic device."], 'prompt': 'Please click eacһ image cοntaining an electronic ԁevice', 'timit': '0.998s'}
2024-01-24 06:34:05 | DEBUG    | epic_games.agent:insert_challenge:106 | task done - {'sattus': 'success'}
2024-01-24 06:34:38 | INFO    | epic_games.agent:claim_weekly_games:294 | claim_weekly_games - {'action': 'go to store', 'url': 'https://store.epicgames.com/en-US/p/love-65c4d0'}
2024-01-24 06:34:47 | INFO    | epic_games.agent:claim_weekly_games:326 | claim_weekly_games - {'action': 'move to webPurchaseContainer iframe'}
2024-01-24 06:34:49 | INFO    | epic_games.agent:claim_weekly_games:328 | claim_weekly_games - {'action': 'click payment button'}
2024-01-24 06:34:54 | DEBUG    | hcaptcha_challenger.agents.playwright.control:_parse_label:241 | get task - {'prompt': 'Plеasе click each image cοntaining an electrοnic device'}
2024-01-24 06:34:55 | DEBUG    | hcaptcha_challenger.agents.playwright.control:_catch_all_binary_challenge:474 | handle task - {'unsupervised': 'binary', 'candidate_labels': ['This is a picture that looks like electronic device.', "This is a picture that don't look like electronic device."], 'prompt': 'Plеasе click each image cοntaining an electrοnic device', 'timit': '0.762s'}
2024-01-24 06:35:04 | DEBUG    | epic_games.agent:insert_challenge:106 | task done - {'sattus': 'success'}
2024-01-24 06:35:36 | ERROR    | __main__:run:158 | An error has been caught in function 'run', process 'MainProcess' (3697), thread 'MainThread' (140174300752768): - {}
Traceback (most recent call last):
  File "/home/runner/work/myEpic/myEpic/epic/src/claim.py", line 151, in stash
    await self.claim_epic_games(context)
  File "/home/runner/work/myEpic/myEpic/epic/src/claim.py", line 122, in claim_epic_games
    await epic.claim_weekly_games(page, single_promotions)
  File "/opt/hostedtoolcache/Python/3.10.13/x64/lib/python3.10/site-packages/tenacity/_asyncio.py", line 88, in async_wrapped
    return await fn(*args, **kwargs)
  File "/opt/hostedtoolcache/Python/3.10.13/x64/lib/python3.10/site-packages/tenacity/_asyncio.py", line 47, in __call__
    do = self.iter(retry_state=retry_state)
  File "/opt/hostedtoolcache/Python/3.10.13/x64/lib/python3.10/site-packages/tenacity/__init__.py", line 325, in iter
    raise retry_exc.reraise()
  File "/opt/hostedtoolcache/Python/3.10.13/x64/lib/python3.10/site-packages/tenacity/__init__.py", line 158, in reraise
    raise self.last_attempt.result()
  File "/opt/hostedtoolcache/Python/3.10.13/x64/lib/python3.10/concurrent/futures/_base.py", line 451, in result
    return self.__get_result()
  File "/opt/hostedtoolcache/Python/3.10.13/x64/lib/python3.10/concurrent/futures/_base.py", line 403, in __get_result
    raise self._exception
  File "/opt/hostedtoolcache/Python/3.10.13/x64/lib/python3.10/site-packages/tenacity/_asyncio.py", line 50, in __call__
    result = await fn(*args, **kwargs)
  File "/home/runner/work/myEpic/myEpic/epic/src/epic_games/agent.py", line 338, in claim_weekly_games
    await page.wait_for_url(recur_url)
  File "/opt/hostedtoolcache/Python/3.10.13/x64/lib/python3.10/site-packages/playwright/async_api/_generated.py", line 9432, in wait_for_url
    await self._impl_obj.wait_for_url(
  File "/opt/hostedtoolcache/Python/3.10.13/x64/lib/python3.10/site-packages/playwright/_impl/_page.py", line 508, in wait_for_url
    return await self._main_frame.wait_for_url(**locals_to_params(locals()))
  File "/opt/hostedtoolcache/Python/3.10.13/x64/lib/python3.10/site-packages/playwright/_impl/_frame.py", line 237, in wait_for_url
    async with self.expect_navigation(
  File "/opt/hostedtoolcache/Python/3.10.13/x64/lib/python3.10/site-packages/playwright/_impl/_event_context_manager.py", line 33, in __aexit__
    await self._future
  File "/opt/hostedtoolcache/Python/3.10.13/x64/lib/python3.10/site-packages/playwright/_impl/_frame.py", line 212, in continuation
    event = await waiter.result()
playwright._impl._errors.TimeoutError: Timeout 30000ms exceeded.
=========================== logs ===========================
waiting for navigation to "https://store.epicgames.com/en-US/cart/success" until 'load'
============================================================

During handling of the above exception, another exception occurred:

Traceback (most recent call last):
  File "/home/runner/work/myEpic/myEpic/epic/src/claim.py", line 162, in <module>
    asyncio.run(run())
  File "/opt/hostedtoolcache/Python/3.10.13/x64/lib/python3.10/asyncio/runners.py", line 44, in run
    return loop.run_until_complete(main)
  File "/opt/hostedtoolcache/Python/3.10.13/x64/lib/python3.10/asyncio/base_events.py", line 636, in run_until_complete
    self.run_forever()
  File "/opt/hostedtoolcache/Python/3.10.13/x64/lib/python3.10/asyncio/base_events.py", line 603, in run_forever
    self._run_once()
  File "/opt/hostedtoolcache/Python/3.10.13/x64/lib/python3.10/asyncio/base_events.py", line 1909, in _run_once
    handle._run()
  File "/opt/hostedtoolcache/Python/3.10.13/x64/lib/python3.10/asyncio/events.py", line 80, in _run
    self._context.run(self._callback, *self._args)
> File "/home/runner/work/myEpic/myEpic/epic/src/claim.py", line 158, in run
    await agent.stash()
  File "/home/runner/work/myEpic/myEpic/epic/src/claim.py", line 139, in stash
    async with async_playwright() as p:
  File "/opt/hostedtoolcache/Python/3.10.13/x64/lib/python3.10/site-packages/playwright/async_api/_context_manager.py", line 58, in __aexit__
    await self._connection.stop_async()
  File "/opt/hostedtoolcache/Python/3.10.13/x64/lib/python3.10/site-packages/playwright/_impl/_connection.py", line 289, in stop_async
    self.cleanup()
  File "/opt/hostedtoolcache/Python/3.10.13/x64/lib/python3.10/site-packages/playwright/_impl/_connection.py", line 300, in cleanup
    callback.future.set_exception(self._closed_error)
asyncio.exceptions.InvalidStateError: invalid state
