2023-10-30 06:27:46 | INFO    | __main__:stash:140 | run - {'image': '20231029', 'version': '0.9.2.post3', 'role': 'EpicPlayer', 'headless': True, 'self_supervised': True}
2023-10-30 06:27:53 | INFO    | __main__:claim_epic_games:96 | Try to flush cookie - {'task': 'claim_epic_games'}
2023-10-30 06:27:56 | SUCCESS    | epic_games.agent:_login:202 | login - {'result': 'Successfully refreshed tokens'}
2023-10-30 06:28:28 | ERROR    | __main__:run:167 | An error has been caught in function 'run', process 'MainProcess' (3672), thread 'MainThread' (139874296171584): - {}
Traceback (most recent call last):
  File "/home/runner/work/myEpic/myEpic/epic/src/claim.py", line 171, in <module>
    asyncio.run(run())
  File "/opt/hostedtoolcache/Python/3.10.13/x64/lib/python3.10/asyncio/runners.py", line 44, in run
    return loop.run_until_complete(main)
  File "/opt/hostedtoolcache/Python/3.10.13/x64/lib/python3.10/asyncio/base_events.py", line 636, in run_until_complete
    self.run_forever()
  File "/opt/hostedtoolcache/Python/3.10.13/x64/lib/python3.10/asyncio/base_events.py", line 603, in run_forever
    self._run_once()
  File "/opt/hostedtoolcache/Python/3.10.13/x64/lib/python3.10/asyncio/base_events.py", line 1909, in _run_once
    handle._run()
  File "/opt/hostedtoolcache/Python/3.10.13/x64/lib/python3.10/asyncio/events.py", line 80, in _run
    self._context.run(self._callback, *self._args)
> File "/home/runner/work/myEpic/myEpic/epic/src/claim.py", line 167, in run
    await agent.stash()
  File "/home/runner/work/myEpic/myEpic/epic/src/claim.py", line 160, in stash
    await self.claim_epic_games(context)
  File "/home/runner/work/myEpic/myEpic/epic/src/claim.py", line 98, in claim_epic_games
    cookies = await epic.flush_token(context)
  File "/home/runner/work/myEpic/myEpic/epic/src/epic_games/agent.py", line 222, in flush_token
    await page.goto("https://www.epicgames.com/account/personal", wait_until="networkidle")
  File "/opt/hostedtoolcache/Python/3.10.13/x64/lib/python3.10/site-packages/playwright/async_api/_generated.py", line 9251, in goto
    await self._impl_obj.goto(
  File "/opt/hostedtoolcache/Python/3.10.13/x64/lib/python3.10/site-packages/playwright/_impl/_page.py", line 473, in goto
    return await self._main_frame.goto(**locals_to_params(locals()))
  File "/opt/hostedtoolcache/Python/3.10.13/x64/lib/python3.10/site-packages/playwright/_impl/_frame.py", line 138, in goto
    await self._channel.send("goto", locals_to_params(locals()))
  File "/opt/hostedtoolcache/Python/3.10.13/x64/lib/python3.10/site-packages/playwright/_impl/_connection.py", line 61, in send
    return await self._connection.wrap_api_call(
  File "/opt/hostedtoolcache/Python/3.10.13/x64/lib/python3.10/site-packages/playwright/_impl/_connection.py", line 490, in wrap_api_call
    return await cb()
  File "/opt/hostedtoolcache/Python/3.10.13/x64/lib/python3.10/site-packages/playwright/_impl/_connection.py", line 99, in inner_send
    result = next(iter(done)).result()
playwright._impl._api_types.TimeoutError: Timeout 30000ms exceeded.
=========================== logs ===========================
navigating to "https://www.epicgames.com/account/personal", waiting until "networkidle"
============================================================
